Workbook

Sheet CURSOS
G4: PROGRAMACIÓN DE CURSOS PRIMER SEMESTRE DEL 2026
G6: ESCUELA DE ADMINISTRACIÓN
M9: EXAMENES | P9: PRUEBA RECUPERATIVA
M10: 30 de junio al 10 de julio | P10: 30 de junio al 10 de julio
B11: CURSOS MINIMOS LICENCIATURA
H12: Clases | I12: Ayudantía | K12: Pruebas | M12: Examen | P12: Prueba Recuperativa
B13: Sigla | C13: Sec. | D13: Créd | E13: Nombre del curso | F13: Prof | G13: Requisitos | H13: Horario | I13: Horario | K13: Día/Módulo | M13: Día | N13: Hora | P13: Día | Q13: Hora
B14: EAA1110 | C14: 1 | D14: 10 | E14: COMPORTAMIENTO ORGANIZACIONAL | F14: G. MUÑOZ | G14: ADMISIÓN | H14: M-J:2 | I14: V:6 | K14: 29/abr:7 y 29/may:7 | M14: 45476 | N14: 8:20 - 10:20 | P14: 45476 | Q14: 0.72916667
B15: EAA1110 | C15: 2 | D15: 10 | E15: COMPORTAMIENTO ORGANIZACIONAL | F15: S. VALENZUELA | G15: ADMISIÓN | H15: M-J:4 | I15: V:6 | K15: 29/abr:7 y 29/may:7 | M15: 45476 | N15: 8:20 - 10:20 | P15: 45476 | Q15: 0.72916667
B16: EAA1110 | C16: 3 | D16: 10 | E16: COMPORTAMIENTO ORGANIZACIONAL | F16: M.E. VIGNEAUX | G16: ADMISIÓN | H16: M-J:4 | I16: V:6 | K16: 29/abr:7 y 29/may:7 | M16: 45476 | N16: 8:20 - 10:20 | P16: 45476 | Q16: 0.72916667
B17: EAA1110 | C17: 4 | D17: 10 | E17: COMPORTAMIENTO ORGANIZACIONAL | F17: E. KAUSEL | G17: ADMISIÓN | H17: L-W:3 | I17: V:6 | K17: 29/abr:7 y 29/may:7 | M17: 45476 | N17: 8:20 - 10:20 | P17: 45476 | Q17: 0.72916667
B18: EAA1110 | C18: 5 | D18: 10 | E18: COMPORTAMIENTO ORGANIZACIONAL | F18: S. VALENZUELA | G18: ADMISIÓN | H18: M-J:5 | I18: V:6 | K18: 29/abr:7 y 29/may:7 | M18: 45476 | N18: 8:20 - 10:20 | P18: 45476 | Q18: 0.72916667
B19: EAA1110 | C19: 6 | D19: 10 | E19: COMPORTAMIENTO ORGANIZACIONAL | F19: G. MUÑOZ | G19: ADMISIÓN | H19: M-J:3 | I19: V:6 | K19: 29/abr:7 y 29/may:7 | M19: 45476 | N19: 8:20 - 10:20 | P19: 45476 | Q19: 0.72916667
B20: EAA1110 | C20: 7 | D20: 10 | E20: COMPORTAMIENTO ORGANIZACIONAL | F20: F. VALDOVINOS | G20: ADMISIÓN | H20: M-J:1 | I20: V:6 | K20: 29/abr:7 y 29/may:7 | M20: 45476 | N20: 8:20 - 10:20 | P20: 45476 | Q20: 0.72916667
B21: EAA1110 | C21: 8 | D21: 10 | E21: COMPORTAMIENTO ORGANIZACIONAL | F21: M.E. VIGNEAUX | G21: ADMISIÓN | H21: M-J:3 | I21: V:6 | K21: 29/abr:7 y 29/may:7 | M21: 45476 | N21: 8:20 - 10:20 | P21: 45476 | Q21: 0.72916667
B22: EAA1210 | C22: 1 | D22: 10 | E22: CONTABILIDAD | F22: J. GÁLVEZ | G22: ADMISIÓN | H22: M-J:3 | I22: V:3/L:7 | K22: 13/abr:7 y 26/may:7 | M22: 45847 | N22: 8:20 - 10:20 | P22: 45847 | Q22: 0.72916667
B23: EAA1210 | C23: 2 | D23: 10 | E23: CONTABILIDAD | F23: H. GODOY | G23: ADMISIÓN | H23: L-W:1 | I23: V:3/L:7 | K23: 13/abr:7 y 26/may:7 | M23: 45847 | N23: 8:20 - 10:20 | P23: 45847 | Q23: 0.72916667
B24: EAA1210 | C24: 3 | D24: 10 | E24: CONTABILIDAD | F24: R. GANA | G24: ADMISIÓN | H24: L-W:3 | I24: V:3/L:7 | K24: 13/abr:7 y 26/may:7 | M24: 45847 | N24: 8:20 - 10:20 | P24: 45847 | Q24: 0.72916667
B25: EAA1210 | C25: 4 | D25: 10 | E25: CONTABILIDAD | F25: J. GÁLVEZ | G25: ADMISIÓN | H25: M-J:4 | I25: V:3/L:7 | K25: 13/abr:7 y 26/may:7 | M25: 45847 | N25: 8:20 - 10:20 | P25: 45847 | Q25: 0.72916667
... B42: EAA2210 | C42: 1 | D42: 10 | E42: TEORÍA FINANCIERA | F42: D. BUCHUK | G42: Admisión 2020 - 2023: EAA2410-EAA1520-IIC1103 Y EAE2110 CON | H42: L-W:3 | I42: V:6 | K42: 14/abr:7 y 1/jun:7 | M42: 45847 | N42: 13:30 - 15:30 | P42: 45847 | Q42: 0.72916667
G43: Admisión 2024 y posteriores: EAA2410-EAA1520-IIC1103 CON Y EAE2110 CON
B44: EAA2210 | C44: 2 | D44: 10 | E44: TEORÍA FINANCIERA | F44: D. BUCHUK | G44: Admisión 2020 - 2023: EAA2410-EAA1520-IIC1103 Y EAE2110 CON | H44: L-W:4 | I44: V:6 | K44: 14/abr:7 y 1/jun:7 | M44: 45847 | N44: 13:30 - 15:30 | P44: 45847 | Q44: 0.72916667
G45: Admisión 2024 y posteriores: EAA2410-EAA1520-IIC1103 CON Y EAE2110 CON
B46: EAA2210 | C46: 3 | D46: 10 | E46: TEORÍA FINANCIERA | F46: M. VALENZUELA | G46: Admisión 2020 - 2023: EAA2410-EAA1520-IIC1103 Y EAE2110 CON | H46: M-J:1 | I46: V:6 | K46: 14/abr:7 y 1/jun:7 | M46: 45847 | N46: 13:30 - 15:30 | P46: 45847 | Q46: 0.72916667
G47: Admisión 2024 y posteriores: EAA2410-EAA1520-IIC1103 CON Y EAE2110 CON
B48: EAA2210 | C48: 4 | D48: 10 | E48: TEORÍA FINANCIERA | F48: C. SILVA | G48: Admisión 2020 - 2023: EAA2410-EAA1520-IIC1103 Y EAE2110 CON | H48: M-J:6 | I48: V:6 | K48: 14/abr:7 y 1/jun:7 | M48: 45847 | N48: 13:30 - 15:30 | P48: 45847 | Q48: 0.72916667
G49: Admisión 2024 y posteriores: EAA2410-EAA1520-IIC1103 CON Y EAE2110 CON
B50: EAA2220 | C50: 1 | D50: 10 | E50: COSTOS | F50: G. MATURANA | G50: EAA2410 | H50: W:2 | I50: V:2 | K50: 10/abr:7 y 15/may:7 | M50: 45475 | N50: 8:20 - 10:20 | P50: 45475 | Q50: 0.72916667
B51: EAA2220 | C51: 2 | D51: 10 | E51: COSTOS | F51: G. MATURANA | G51: EAA2410 | H51: W:3 | I51: V:2 | K51: 10/abr:7 y 15/may:7 | M51: 45475 | N51: 8:20 - 10:20 | P51: 45475 | Q51: 0.72916667
B52: EAA2220 | C52: 3 | D52: 10 | E52: COSTOS | F52: M. DEL SANTE | G52: EAA2410 | H52: M:3 | I52: V:2 | K52: 10/abr:7 y 15/may:7 | M52: 45475 | N52: 8:20 - 10:20 | P52: 45475 | Q52: 0.72916667
B53: EAA2220 | C53: 4 | D53: 10 | E53: COSTOS | F53: M. DEL SANTE | G53: EAA2410 | H53: M:4 | I53: V:2 | K53: 10/abr:7 y 15/may:7 | M53: 45475 | N53: 8:20 - 10:20 | P53: 45475 | Q53: 0.72916667
B54: EAA223A | C54: 1 | D54: 10 | E54: CONTABILIDAD GERENCIAL | F54: I. RODRÍGUEZ | G54: EAA218A y EAA220B | H54: M-J:3 | I54: V:6 | K54: 14/abr:7 y 1/jun:7 | M54: 45847 | N54: 8:20 - 10:20 | P54: 45847 | Q54: 0.72916667
B55: EAA223A | C55: 2 | D55: 10 | E55: CONTABILIDAD GERENCIAL | F55: M. DEL SANTE | G55: EAA218A y EAA220B | H55: L-W:2 | I55: V:6 | K55: 14/abr:7 y 1/jun:7 | M55: 45847 | N55: 8:20 - 10:20 | P55: 45847 | Q55: 0.72916667
B56: EAA223A | C56: 3 | D56: 10 | E56: CONTABILIDAD GERENCIAL | F56: M. DEL SANTE | G56: EAA218A y EAA220B | H56: L-W:4 | I56: V:6 | K56: 14/abr:7 y 1/jun:7 | M56: 45847 | N56: 8:20 - 10:20 | P56: 45847 | Q56: 0.72916667
B57: EAA223A | C57: 4 | D57: 10 | E57: CONTABILIDAD GERENCIAL | F57: L.CAMILLA | G57: EAA218A y EAA220B | H57: L-W:1 | I57: V:6 | K57: 14/abr:7 y 1/jun:7 | M57: 45847 | N57: 8:20 - 10:20 | P57: 45847 | Q57: 0.72916667
B58: EAA2240 | C58: 1 | D58: 10 | E58: CONTABILIDAD GERENCIAL | F58: I. RODRÍGUEZ | G58: EAA2210 y EAA2220 | H58: M-J:3 | I58: V:6 | K58: 14/abr:7 y 1/jun:7 | M58: 45847 | N58: 8:20 - 10:20 | P58: 45847 | Q58: 0.72916667
B59: EAA2240 | C59: 2 | D59: 10 | E59: CONTABILIDAD GERENCIAL | F59: M. DEL SANTE | G59: EAA2210 y EAA2220 | H59: L-W:2 | I59: V:6 | K59: 14/abr:7 y 1/jun:7 | M59: 45847 | N59: 8:20 - 10:20 | P59: 45847 | Q59: 0.72916667
B60: EAA2240 | C60: 3 | D60: 10 | E60: CONTABILIDAD GERENCIAL | F60: M. DEL SANTE | G60: EAA2210 y EAA2220 | H60: L-W:4 | I60: V:6 | K60: 14/abr:7 y 1/jun:7 | M60: 45847 | N60: 8:20 - 10:20 | P60: 45847 | Q60: 0.72916667
B61: EAA2240 | C61: 4 | D61: 10 | E61: CONTABILIDAD GERENCIAL | F61: L.CAMILLA | G61: EAA2210 y EAA2220 | H61: L-W:1 | I61: V:6 | K61: 14/abr:7 y 1/jun:7 | M61: 45847 | N61: 8:20 - 10:20 | P61: 45847 | Q61: 0.72916667
... B92: EAA1520 | C92: 5 | D92: 10 | E92: INFERENCIA ESTADÍSTICA | F92: R. ARAVENA | G92: EAA1510 | H92: M-J:2 | I92: L:6 - L:3 | K92: 27/abr:7 y 5/jun:7 | M92: 45481 | N92: 8:20 - 10:20 | P92: 45481 | Q92: 0.72916667
...

Sheet VACANTES
F1: PONTIFICIA UNIVERSIDAD CATOLICA DE CHILE
F2: ESCUELA DE ADMINISTRACION
F3: PROGRAMACIÓN DE CURSOS SEGUNDO DEL 2006
B5: CURSOS MINIMOS LICENCIATURA
K6: =SUM(K8:K40)+SUM(K58:K67)+SUM(K72:K80)+SUM(K85:K93)+SUM(K97:K102)+SUM(K106:K133)+SUM(K138:K144)+SUM(K151:K178)+SUM(K185:K196)+SUM(K208:K209)+SUM(K216:K222) -> 501 | L6: =SUM(L8:L40)+SUM(L58:L67)+SUM(L72:L80)+SUM(L85:L93)+SUM(L97:L102)+SUM(L106:L133)+SUM(L138:L144)+SUM(L151:L178)+SUM(L185:L196)+SUM(L208:L209)+SUM(L216:L222) -> 305
A7: Sigla | B7: Sigla | C7: Sec. | D7: Créd | E7: Nombre del curso | F7: Prof | G7: Requisitos | H7: UA05 | I7: UA11 | J7: UA07 | K7: FG | L7: INTERC. | M7: Juan Edo. | N7: TOTAL | O7: Sala | P7: Nº alumnos/Sala
A8: =+#REF! -> #REF! | B8: =+#REF! -> #REF! | C8: =+#REF! -> #REF! | D8: =+#REF! -> #REF! | E8: =+#REF! -> #REF! | F8: =+#REF! -> #REF! | G8: =+#REF! -> #REF! | H8: 55 | K8: 5 | L8: 5 | N8: =SUM(H8:L8) -> 65 | O8: =+#REF! -> #REF! | P8: 80
A9: =+#REF! -> #REF! | B9: =+#REF! -> #REF! | C9: =+#REF! -> #REF! | D9: =+#REF! -> #REF! | E9: =+#REF! -> #REF! | F9: =+#REF! -> #REF! | G9: =+#REF! -> #REF! | H9: 55 | K9: 5 | L9: 5 | N9: =SUM(H9:L9) -> 65 | O9: =+#REF! -> #REF! | P9: 100
A10: =+#REF! -> #REF! | B10: =+#REF! -> #REF! | C10: =+#REF! -> #REF! | D10: =+#REF! -> #REF! | E10: =+#REF! -> #REF! | F10: =+#REF! -> #REF! | G10: =+#REF! -> #REF! | H10: 55 | K10: 5 | L10: 5 | N10: =SUM(H10:L10) -> 65 | O10: =+#REF! -> #REF! | P10: 80
A11: =+#REF! -> #REF! | B11: =+#REF! -> #REF! | C11: =+#REF! -> #REF! | D11: =+#REF! -> #REF! | E11: =+#REF! -> #REF! | F11: =+#REF! -> #REF! | G11: =+#REF! -> #REF! | H11: 55 | K11: 5 | L11: 5 | N11: =SUM(H11:L11) -> 65 | O11: =+#REF! -> #REF! | P11: 100
A12: =+#REF! -> #REF! | B12: =+#REF! -> #REF! | C12: =+#REF! -> #REF! | D12: =+#REF! -> #REF! | E12: =+#REF! -> #REF! | F12: =+#REF! -> #REF! | G12: =+#REF! -> #REF! | H12: 40 | J12: 15 | K12: 5 | L12: 3 | N12: =SUM(H12:L12) -> 63 | O12: =+#REF! -> #REF! | P12: 75
A13: =+#REF! -> #REF! | B13: =+#REF! -> #REF! | C13: =+#REF! -> #REF! | D13: =+#REF! -> #REF! | E13: =+#REF! -> #REF! | F13: =+#REF! -> #REF! | G13: =+#REF! -> #REF! | H13: 40 | J13: 15 | K13: 5 | L13: 3 | N13: =SUM(H13:L13) -> 63 | O13: =+#REF! -> #REF! | P13: 60
A14: =+#REF! -> #REF! | B14: =+#REF! -> #REF! | C14: =+#REF! -> #REF! | D14: =+#REF! -> #REF! | E14: =+#REF! -> #REF! | F14: =+#REF! -> #REF! | G14: =+#REF! -> #REF! | H14: 51 | J14: 14 | K14: 5 | N14: =SUM(H14:L14) -> 70 | O14: =+#REF! -> #REF! | P14: 120
A15: =+#REF! -> #REF! | B15: =+#REF! -> #REF! | C15: =+#REF! -> #REF! | D15: =+#REF! -> #REF! | E15: =+#REF! -> #REF! | F15: =+#REF! -> #REF! | G15: =+#REF! -> #REF! | H15: 51 | J15: 14 | K15: 5 | N15: =SUM(H15:L15) -> 70 | O15: =+#REF! -> #REF! | P15: 110
A16: =+#REF! -> #REF! | B16: =+#REF! -> #REF! | C16: =+#REF! -> #REF! | D16: =+#REF! -> #REF! | E16: =+#REF! -> #REF! | F16: =+#REF! -> #REF! | G16: =+#REF! -> #REF! | H16: 51 | J16: 14 | K16: 5 | N16: =SUM(H16:L16) -> 70 | O16: =+#REF! -> #REF! | P16: 80
A17: =+#REF! -> #REF! | B17: =+#REF! -> #REF! | C17: =+#REF! -> #REF! | D17: =+#REF! -> #REF! | E17: =+#REF! -> #REF! | F17: =+#REF! -> #REF! | G17: =+#REF! -> #REF! | H17: 51 | J17: 14 | K17: 5 | N17: =SUM(H17:L17) -> 70 | O17: =+#REF! -> #REF! | P17: 110
A18: =+#REF! -> #REF! | B18: =+#REF! -> #REF! | C18: =+#REF! -> #REF! | D18: =+#REF! -> #REF! | E18: =+#REF! -> #REF! | F18: =+#REF! -> #REF! | G18: =+#REF! -> #REF! | H18: 45 | K18: 5 | L18: 5 | N18: =SUM(H18:L18) -> 55 | O18: =+#REF! -> #REF! | P18: 75
A19: =+#REF! -> #REF! | B19: =+#REF! -> #REF! | C19: =+#REF! -> #REF! | D19: =+#REF! -> #REF! | E19: =+#REF! -> #REF! | F19: =+#REF! -> #REF! | G19: =+#REF! -> #REF! | H19: 45 | K19: 5 | L19: 5 | N19: =SUM(H19:L19) -> 55 | O19: =+#REF! -> #REF! | P19: 60
A20: =+#REF! -> #REF! | B20: =+#REF! -> #REF! | C20: =+#REF! -> #REF! | D20: =+#REF! -> #REF! | E20: =+#REF! -> #REF! | F20: =+#REF! -> #REF! | G20: =+#REF! -> #REF! | H20: 50 | K20: 5 | N20: =SUM(H20:L20) -> 55 | O20: =+#REF! -> #REF! | P20: 100
A21: =+#REF! -> #REF! | B21: =+#REF! -> #REF! | C21: =+#REF! -> #REF! | D21: =+#REF! -> #REF! | E21: =+#REF! -> #REF! | F21: =+#REF! -> #REF! | G21: =+#REF! -> #REF! | H21: 50 | K21: 5 | N21: =SUM(H21:L21) -> 55 | O21: =+#REF! -> #REF! | P21: 56
A22: =+#REF! -> #REF! | B22: =+#REF! -> #REF! | C22: =+#REF! -> #REF! | D22: =+#REF! -> #REF! | E22: =+#REF! -> #REF! | F22: =+#REF! -> #REF! | G22: =+#REF! -> #REF! | H22: 65 | K22: 5 | N22: =SUM(H22:L22) -> 70 | O22: =+#REF! -> #REF! | P22: 120
A23: =+#REF! -> #REF! | B23: =+#REF! -> #REF! | C23: =+#REF! -> #REF! | D23: =+#REF! -> #REF! | E23: =+#REF! -> #REF! | F23: =+#REF! -> #REF! | G23: =+#REF! -> #REF! | H23: 55 | K23: 5 | N23: =SUM(H23:L23) -> 60 | O23: =+#REF! -> #REF! | P23: 60
A24: =+#REF! -> #REF! | B24: =+#REF! -> #REF! | C24: =+#REF! -> #REF! | D24: =+#REF! -> #REF! | E24: =+#REF! -> #REF! | F24: =+#REF! -> #REF! | G24: =+#REF! -> #REF! | H24: 65 | K24: 5 | L24: 5 | N24: =SUM(H24:L24) -> 75 | O24: =+#REF! -> #REF! | P24: 110
A25: =+#REF! -> #REF! | B25: =+#REF! -> #REF! | C25: =+#REF! -> #REF! | D25: =+#REF! -> #REF! | E25: =+#REF! -> #REF! | F25: =+#REF! -> #REF! | G25: =+#REF! -> #REF! | H25: 65 | K25: 5 | L25: 5 | N25: =SUM(H25:L25) -> 75 | O25: =+#REF! -> #REF! | P25: 100
A26: =+#REF! -> #REF! | B26: =+#REF! -> #REF! | C26: =+#REF! -> #REF! | D26: =+#REF! -> #REF! | E26: =+#REF! -> #REF! | F26: =+#REF! -> #REF! | G26: =+#REF! -> #REF! | H26: 55 | K26: 5 | N26: =SUM(H26:L26) -> 60 | O26: =+#REF! -> #REF! | P26: 60
A27: =+#REF! -> #REF! | B27: =+#REF! -> #REF! | C27: =+#REF! -> #REF! | D27: =+#REF! -> #REF! | E27: =+#REF! -> #REF! | F27: =+#REF! -> #REF! | G27: =+#REF! -> #REF! | H27: 55 | K27: 5 | L27: 5 | N27: =SUM(H27:L27) -> 65 | O27: =+#REF! -> #REF! | P27: 120
A28: =+#REF! -> #REF! | B28: =+#REF! -> #REF! | C28: =+#REF! -> #REF! | D28: =+#REF! -> #REF! | E28: =+#REF! -> #REF! | F28: =+#REF! -> #REF! | G28: =+#REF! -> #REF! | H28: 55 | K28: 5 | N28: =SUM(H28:L28) -> 60 | O28: =+#REF! -> #REF! | P28: 60
A29: =+#REF! -> #REF! | B29: =+#REF! -> #REF! | C29: =+#REF! -> #REF! | D29: =+#REF! -> #REF! | E29: =+#REF! -> #REF! | F29: =+#REF! -> #REF! | G29: =+#REF! -> #REF! | H29: 60 | L29: 5 | N29: =SUM(H29:L29) -> 65 | O29: =+#REF! -> #REF! | P29: 75
A30: =+#REF! -> #REF! | B30: =+#REF! -> #REF! | C30: =+#REF! -> #REF! | D30: =+#REF! -> #REF! | E30: =+#REF! -> #REF! | F30: =+#REF! -> #REF! | G30: =+#REF! -> #REF! | H30: 60 | L30: 5 | N30: =SUM(H30:L30) -> 65 | O30: =+#REF! -> #REF! | P30: 110
A31: =+#REF! -> #REF! | B31: =+#REF! -> #REF! | C31: =+#REF! -> #REF! | D31: =+#REF! -> #REF! | E31: =+#REF! -> #REF! | F31: =+#REF! -> #REF! | G31: =+#REF! -> #REF! | H31: 60 | K31: 5 | L31: 5 | N31: =SUM(H31:L31) -> 70 | O31: =+#REF! -> #REF! | P31: 100
A32: =+#REF! -> #REF! | B32: =+#REF! -> #REF! | C32: =+#REF! -> #REF! | D32: =+#REF! -> #REF! | E32: =+#REF! -> #REF! | F32: =+#REF! -> #REF! | G32: =+#REF! -> #REF! | H32: 60 | K32: 5 | L32: 5 | N32: =SUM(H32:L32) -> 70 | O32: =+#REF! -> #REF! | P32: 100
A33: =+#REF! -> #REF! | B33: =+#REF! -> #REF! | C33: =+#REF! -> #REF! | D33: =+#REF! -> #REF! | E33: =+#REF! -> #REF! | F33: =+#REF! -> #REF! | G33: =+#REF! -> #REF! | H33: 55 | K33: 5 | L33: 2 | N33: =SUM(H33:L33) -> 62 | O33: =+#REF! -> #REF! | P33: 75
A34: =+#REF! -> #REF! | B34: =+#REF! -> #REF! | C34: =+#REF! -> #REF! | D34: =+#REF! -> #REF! | E34: =+#REF! -> #REF! | F34: =+#REF! -> #REF! | G34: =+#REF! -> #REF! | H34: 55 | K34: 5 | L34: 2 | N34: =SUM(H34:L34) -> 62 | O34: =+#REF! -> #REF! | P34: 80
A35: =+#REF! -> #REF! | B35: =+#REF! -> #REF! | C35: =+#REF! -> #REF! | D35: =+#REF! -> #REF! | E35: =+#REF! -> #REF! | F35: =+#REF! -> #REF! | G35: =+#REF! -> #REF! | H35: 55 | K35: 5 | N35: =SUM(H35:L35) -> 60 | O35: =+#REF! -> #REF! | P35: 60
A36: =+#REF! -> #REF! | B36: =+#REF! -> #REF! | C36: =+#REF! -> #REF! | D36: =+#REF! -> #REF! | E36: =+#REF! -> #REF! | F36: =+#REF! -> #REF! | G36: =+#REF! -> #REF! | H36: 55 | J36: 20 | K36: 3 | N36: =SUM(H36:L36) -> 78 | O36: =+#REF! -> #REF! | P36: 110
A37: =+#REF! -> #REF! | B37: =+#REF! -> #REF! | C37: =+#REF! -> #REF! | D37: =+#REF! -> #REF! | E37: =+#REF! -> #REF! | F37: =+#REF! -> #REF! | G37: =+#REF! -> #REF! | H37: 55 | J37: 20 | K37: 3 | N37: =SUM(H37:L37) -> 78 | O37: =+#REF! -> #REF! | P37: 80
A38: =+#REF! -> #REF! | B38: =+#REF! -> #REF! | C38: =+#REF! -> #REF! | D38: =+#REF! -> #REF! | E38: =+#REF! -> #REF! | F38: =+#REF! -> #REF! | G38: =+#REF! -> #REF! | H38: 63 | J38: 7 | N38: =SUM(H38:L38) -> 70 | O38: =+#REF! -> #REF! | P38: 100
A39: =+#REF! -> #REF! | B39: =+#REF! -> #REF! | C39: =+#REF! -> #REF! | D39: =+#REF! -> #REF! | E39: =+#REF! -> #REF! | F39: =+#REF! -> #REF! | G39: =+#REF! -> #REF! | H39: 63 | J39: 7 | N39: =SUM(H39:L39) -> 70 | O39: =+#REF! -> #REF! | P39: 75
A40: =+#REF! -> #REF! | B40: =+#REF! -> #REF! | C40: =+#REF! -> #REF! | D40: =+#REF! -> #REF! | E40: =+#REF! -> #REF! | F40: =+#REF! -> #REF! | G40: =+#REF! -> #REF! | H40: 63 | J40: 7 | N40: =SUM(H40:L40) -> 70 | O40: =+#REF! -> #REF! | P40: 120
B41: =+#REF! -> #REF! | C41: =+#REF! -> #REF! | D41: =+#REF! -> #REF! | E41: =+#REF! -> #REF! | F41: =+#REF! -> #REF! | G41: =+#REF! -> #REF! | H41: 23 | O41: =+#REF! -> #REF!
...

Sheet Hoja1
E1: PONTIFICIA UNIVERSIDAD CATOLICA DE CHILE
E2: ESCUELA DE ADMINISTRACION
E3: PROGRAMACIÓN DE CURSOS SEGUNDO SEMESTRE DEL 2006
A5: CURSOS MINIMOS LICENCIATURA
M6: VACANTES
A7: Sigla | B7: Sec. | C7: Créd | D7: Nombre del curso | E7: Prof | F7: RUT | G7: Requisitos | H7: Hor. | I7: Sala | J7: Hor. | K7: Sala | M7: UA05 | N7: UA11 | O7: UA07 | P7: FG | Q7: INTERCAMBIO | R7: TOTAL | S7: TOTAL
A8: =+#REF! -> #REF! | B8: =+#REF! -> #REF! | C8: =+#REF! -> #REF! | D8: =+#REF! -> #REF! | E8: =+#REF! -> #REF! | F8: 5593247-6 | G8: =IF(D8="","",VLOOKUP(MID(A8,1,7),#REF!,3,FALSE)) -> #REF! | H8: =+#REF! -> #REF! | I8: =+#REF! -> #REF! | J8: =+#REF! -> #REF! | K8: =+#REF! -> #REF! | M8: =+VACANTES!H8 -> 55 | N8: =+VACANTES!I8 -> 0 | O8: =+VACANTES!J8 -> 0 | P8: =+VACANTES!K8 -> 5 | Q8: =+VACANTES!L8 -> 5 | R8: =+VACANTES!N8 -> 65 | S8: =+R8-Q8 -> 60
A9: =+#REF! -> #REF! | B9: =+#REF! -> #REF! | C9: =+#REF! -> #REF! | D9: =+#REF! -> #REF! | E9: =+#REF! -> #REF! | F9: 6062116-0 | G9: =IF(D9="","",VLOOKUP(MID(A9,1,7),#REF!,3,FALSE)) -> #REF! | H9: =+#REF! -> #REF! | I9: =+#REF! -> #REF! | J9: =+#REF! -> #REF! | K9: =+#REF! -> #REF! | M9: =+VACANTES!H9 -> 55 | N9: =+VACANTES!I9 -> 0 | O9: =+VACANTES!J9 -> 0 | P9: =+VACANTES!K9 -> 5 | Q9: =+VACANTES!L9 -> 5 | R9: =+VACANTES!N9 -> 65 | S9: =+R9-Q9 -> 60
A10: =+#REF! -> #REF! | B10: =+#REF! -> #REF! | C10: =+#REF! -> #REF! | D10: =+#REF! -> #REF! | E10: N.N | G10: =IF(D10="","",VLOOKUP(MID(A10,1,7),#REF!,3,FALSE)) -> #REF! | J10: =+#REF! -> #REF! | K10: =+#REF! -> #REF! | M10: =+VACANTES!H10 -> 55 | N10: =+VACANTES!I10 -> 0 | O10: =+VACANTES!J10 -> 0 | P10: =+VACANTES!K10 -> 5 | Q10: =+VACANTES!L10 -> 5 | R10: =+VACANTES!N10 -> 65 | S10: =+R10-Q10 -> 60
A11: =+#REF! -> #REF! | B11: =+#REF! -> #REF! | C11: =+#REF! -> #REF! | D11: =+#REF! -> #REF! | E11: =+#REF! -> #REF! | F11: 8122891-4 | G11: =IF(D11="","",VLOOKUP(MID(A11,1,7),#REF!,3,FALSE)) -> #REF! | H11: =+#REF! -> #REF! | I11: =+#REF! -> #REF! | J11: =+#REF! -> #REF! | K11: =+#REF! -> #REF! | M11: =+VACANTES!H11 -> 55 | N11: =+VACANTES!I11 -> 0 | O11: =+VACANTES!J11 -> 0 | P11: =+VACANTES!K11 -> 5 | Q11: =+VACANTES!L11 -> 5 | R11: =+VACANTES!N11 -> 65 | S11: =+R11-Q11 -> 60
A12: =+#REF! -> #REF! | B12: =+#REF! -> #REF! | C12: =+#REF! -> #REF! | D12: =+#REF! -> #REF! | E12: N.N | G12: =IF(D12="","",VLOOKUP(MID(A12,1,7),#REF!,3,FALSE)) -> #REF! | I12: =+#REF! -> #REF! | J12: =+#REF! -> #REF! | K12: =+#REF! -> #REF! | M12: =+VACANTES!H12 -> 40 | N12: =+VACANTES!I12 -> 0 | O12: =+VACANTES!J12 -> 15 | P12: =+VACANTES!K12 -> 5 | Q12: =+VACANTES!L12 -> 3 | R12: =+VACANTES!N12 -> 63 | S12: =+R12-Q12 -> 60
A13: =+#REF! -> #REF! | B13: =+#REF! -> #REF! | C13: =+#REF! -> #REF! | D13: =+#REF! -> #REF! | E13: =+#REF! -> #REF! | G13: =IF(D13="","",VLOOKUP(MID(A13,1,7),#REF!,3,FALSE)) -> #REF! | H13: =+#REF! -> #REF! | I13: =+#REF! -> #REF! | J13: =+#REF! -> #REF! | K13: =+#REF! -> #REF! | M13: =+VACANTES!H13 -> 40 | N13: =+VACANTES!I13 -> 0 | O13: =+VACANTES!J13 -> 15 | P13: =+VACANTES!K13 -> 5 | Q13: =+VACANTES!L13 -> 3 | R13: =+VACANTES!N13 -> 63 | S13: =+R13-Q13 -> 60
A14: =+#REF! -> #REF! | B14: =+#REF! -> #REF! | C14: =+#REF! -> #REF! | D14: =+#REF! -> #REF! | E14: =+#REF! -> #REF! | F14: 7274560-4 | G14: =IF(D14="","",VLOOKUP(MID(A14,1,7),#REF!,3,FALSE)) -> #REF! | H14: =+#REF! -> #REF! | I14: =+#REF! -> #REF! | J14: =+#REF! -> #REF! | K14: =+#REF! -> #REF! | M14: =+VACANTES!H14 -> 51 | N14: =+VACANTES!I14 -> 0 | O14: =+VACANTES!J14 -> 14 | P14: =+VACANTES!K14 -> 5 | Q14: =+VACANTES!L14 -> 0 | R14: =+VACANTES!N14 -> 70 | S14: =+R14-Q14 -> 70
A15: =+#REF! -> #REF! | B15: =+#REF! -> #REF! | C15: =+#REF! -> #REF! | D15: =+#REF! -> #REF! | E15: =+#REF! -> #REF! | F15: 15379452-9 | G15: =IF(D15="","",VLOOKUP(MID(A15,1,7),#REF!,3,FALSE)) -> #REF! | H15: =+#REF! -> #REF! | I15: =+#REF! -> #REF! | J15: =+#REF! -> #REF! | K15: =+#REF! -> #REF! | M15: =+VACANTES!H15 -> 51 | N15: =+VACANTES!I15 -> 0 | O15: =+VACANTES!J15 -> 14 | P15: =+VACANTES!K15 -> 5 | Q15: =+VACANTES!L15 -> 0 | R15: =+VACANTES!N15 -> 70 | S15: =+R15-Q15 -> 70
A16: =+#REF! -> #REF! | B16: =+#REF! -> #REF! | C16: =+#REF! -> #REF! | D16: =+#REF! -> #REF! | E16: =+#REF! -> #REF! | F16: 15312093-5 | G16: =IF(D16="","",VLOOKUP(MID(A16,1,7),#REF!,3,FALSE)) -> #REF! | H16: =+#REF! -> #REF! | I16: =+#REF! -> #REF! | J16: =+#REF! -> #REF! | K16: =+#REF! -> #REF! | M16: =+VACANTES!H16 -> 51 | N16: =+VACANTES!I16 -> 0 | O16: =+VACANTES!J16 -> 14 | P16: =+VACANTES!K16 -> 5 | Q16: =+VACANTES!L16 -> 0 | R16: =+VACANTES!N16 -> 70 | S16: =+R16-Q16 -> 70
A17: =+#REF! -> #REF! | B17: =+#REF! -> #REF! | C17: =+#REF! -> #REF! | D17: =+#REF! -> #REF! | E17: =+#REF! -> #REF! | F17: 10034247-2 | G17: =IF(D17="","",VLOOKUP(MID(A17,1,7),#REF!,3,FALSE)) -> #REF! | H17: =+#REF! -> #REF! | I17: =+#REF! -> #REF! | J17: =+#REF! -> #REF! | K17: =+#REF! -> #REF! | M17: =+VACANTES!H17 -> 51 | N17: =+VACANTES!I17 -> 0 | O17: =+VACANTES!J17 -> 14 | P17: =+VACANTES!K17 -> 5 | Q17: =+VACANTES!L17 -> 0 | R17: =+VACANTES!N17 -> 70 | S17: =+R17-Q17 -> 70
A18: =+#REF! -> #REF! | B18: =+#REF! -> #REF! | C18: =+#REF! -> #REF! | D18: =+#REF! -> #REF! | E18: =+#REF! -> #REF! | F18: 9580246-K | G18: =IF(D18="","",VLOOKUP(MID(A18,1,7),#REF!,3,FALSE)) -> #REF! | H18: =+#REF! -> #REF! | I18: =+#REF! -> #REF! | J18: =+#REF! -> #REF! | K18: =+#REF! -> #REF! | M18: =+VACANTES!H18 -> 45 | N18: =+VACANTES!I18 -> 0 | O18: =+VACANTES!J18 -> 0 | P18: =+VACANTES!K18 -> 5 | Q18: =+VACANTES!L18 -> 5 | R18: =+VACANTES!N18 -> 55 | S18: =+R18-Q18 -> 50
A19: =+#REF! -> #REF! | B19: =+#REF! -> #REF! | C19: =+#REF! -> #REF! | D19: =+#REF! -> #REF! | E19: =+#REF! -> #REF! | F19: 8530082-2 | G19: =IF(D19="","",VLOOKUP(MID(A19,1,7),#REF!,3,FALSE)) -> #REF! | H19: =+#REF! -> #REF! | I19: =+#REF! -> #REF! | J19: =+#REF! -> #REF! | K19: =+#REF! -> #REF! | M19: =+VACANTES!H19 -> 45 | N19: =+VACANTES!I19 -> 0 | O19: =+VACANTES!J19 -> 0 | P19: =+VACANTES!K19 -> 5 | Q19: =+VACANTES!L19 -> 5 | R19: =+VACANTES!N19 -> 55 | S19: =+R19-Q19 -> 50
A20: =+#REF! -> #REF! | B20: =+#REF! -> #REF! | C20: =+#REF! -> #REF! | D20: =+#REF! -> #REF! | E20: =+#REF! -> #REF! | F20: 9681304-K | G20: =IF(D20="","",VLOOKUP(MID(A20,1,7),#REF!,3,FALSE)) -> #REF! | H20: =+#REF! -> #REF! | I20: =+#REF! -> #REF! | J20: =+#REF! -> #REF! | K20: =+#REF! -> #REF! | M20: =+VACANTES!H20 -> 50 | N20: =+VACANTES!I20 -> 0 | O20: =+VACANTES!J20 -> 0 | P20: =+VACANTES!K20 -> 5 | Q20: =+VACANTES!L20 -> 0 | R20: =+VACANTES!N20 -> 55 | S20: =+R20-Q20 -> 55
A21: =+#REF! -> #REF! | B21: =+#REF! -> #REF! | C21: =+#REF! -> #REF! | D21: =+#REF! -> #REF! | E21: N.N | G21: =IF(D21="","",VLOOKUP(MID(A21,1,7),#REF!,3,FALSE)) -> #REF! | H21: =+#REF! -> #REF! | I21: =+#REF! -> #REF! | J21: =+#REF! -> #REF! | K21: =+#REF! -> #REF! | M21: =+VACANTES!H21 -> 50 | N21: =+VACANTES!I21 -> 0 | O21: =+VACANTES!J21 -> 0 | P21: =+VACANTES!K21 -> 5 | Q21: =+VACANTES!L21 -> 0 | R21: =+VACANTES!N21 -> 55 | S21: =+R21-Q21 -> 55
A22: =+#REF! -> #REF! | B22: =+#REF! -> #REF! | C22: =+#REF! -> #REF! | D22: =+#REF! -> #REF! | E22: =+#REF! -> #REF! | F22: 9669736-8 | G22: =IF(D22="","",VLOOKUP(MID(A22,1,7),#REF!,3,FALSE)) -> #REF! | H22: =+#REF! -> #REF! | I22: =+#REF! -> #REF! | J22: =+#REF! -> #REF! | K22: =+#REF! -> #REF! | M22: =+VACANTES!H22 -> 65 | N22: =+VACANTES!I22 -> 0 | O22: =+VACANTES!J22 -> 0 | P22: =+VACANTES!K22 -> 5 | Q22: =+VACANTES!L22 -> 0 | R22: =+VACANTES!N22 -> 70 | S22: =+R22-Q22 -> 70
A23: =+#REF! -> #REF! | B23: =+#REF! -> #REF! | C23: =+#REF! -> #REF! | D23: =+#REF! -> #REF! | E23: =+#REF! -> #REF! | F23: 13702582-5 | G23: =IF(D23="","",VLOOKUP(MID(A23,1,7),#REF!,3,FALSE)) -> #REF! | H23: =+#REF! -> #REF! | I23: =+#REF! -> #REF! | J23: =+#REF! -> #REF! | K23: =+#REF! -> #REF! | M23: =+VACANTES!H23 -> 55 | N23: =+VACANTES!I23 -> 0 | O23: =+VACANTES!J23 -> 0 | P23: =+VACANTES!K23 -> 5 | Q23: =+VACANTES!L23 -> 0 | R23: =+VACANTES!N23 -> 60 | S23: =+R23-Q23 -> 60
A24: =+#REF! -> #REF! | B24: =+#REF! -> #REF! | C24: =+#REF! -> #REF! | D24: =+#REF! -> #REF! | E24: =+#REF! -> #REF! | F24: 3639231-2 | G24: =IF(D24="","",VLOOKUP(MID(A24,1,7),#REF!,3,FALSE)) -> #REF! | H24: =+#REF! -> #REF! | I24: =+#REF! -> #REF! | J24: =+#REF! -> #REF! | K24: =+#REF! -> #REF! | M24: =+VACANTES!H24 -> 65 | N24: =+VACANTES!I24 -> 0 | O24: =+VACANTES!J24 -> 0 | P24: =+VACANTES!K24 -> 5 | Q24: =+VACANTES!L24 -> 5 | R24: =+VACANTES!N24 -> 75 | S24: =+R24-Q24 -> 70
A25: =+#REF! -> #REF! | B25: =+#REF! -> #REF! | C25: =+#REF! -> #REF! | D25: =+#REF! -> #REF! | E25: =+#REF! -> #REF! | F25: 13039736-0 | G25: =IF(D25="","",VLOOKUP(MID(A25,1,7),#REF!,3,FALSE)) -> #REF! | H25: =+#REF! -> #REF! | I25: =+#REF! -> #REF! | J25: =+#REF! -> #REF! | K25: =+#REF! -> #REF! | M25: =+VACANTES!H25 -> 65 | N25: =+VACANTES!I25 -> 0 | O25: =+VACANTES!J25 -> 0 | P25: =+VACANTES!K25 -> 5 | Q25: =+VACANTES!L25 -> 5 | R25: =+VACANTES!N25 -> 75 | S25: =+R25-Q25 -> 70
A26: =+#REF! -> #REF! | B26: =+#REF! -> #REF! | C26: =+#REF! -> #REF! | D26: =+#REF! -> #REF! | E26: =+#REF! -> #REF! | F26: 17947504-9 | G26: =IF(D26="","",VLOOKUP(MID(A26,1,7),#REF!,3,FALSE)) -> #REF! | H26: =+#REF! -> #REF! | I26: =+#REF! -> #REF! | J26: =+#REF! -> #REF! | K26: =+#REF! -> #REF! | M26: =+VACANTES!H26 -> 55 | N26: =+VACANTES!I26 -> 0 | O26: =+VACANTES!J26 -> 0 | P26: =+VACANTES!K26 -> 5 | Q26: =+VACANTES!L26 -> 0 | R26: =+VACANTES!N26 -> 60 | S26: =+R26-Q26 -> 60
A27: =+#REF! -> #REF! | B27: =+#REF! -> #REF! | C27: =+#REF! -> #REF! | D27: =+#REF! -> #REF! | E27: =+#REF! -> #REF! | F27: 7274560-4 | G27: =IF(D27="","",VLOOKUP(MID(A27,1,7),#REF!,3,FALSE)) -> #REF! | H27: =+#REF! -> #REF! | I27: =+#REF! -> #REF! | J27: =+#REF! -> #REF! | K27: =+#REF! -> #REF! | M27: =+VACANTES!H27 -> 55 | N27: =+VACANTES!I27 -> 0 | O27: =+VACANTES!J27 -> 0 | P27: =+VACANTES!K27 -> 5 | Q27: =+VACANTES!L27 -> 5 | R27: =+VACANTES!N27 -> 65 | S27: =+R27-Q27 -> 60
A28: =+#REF! -> #REF! | B28: =+#REF! -> #REF! | C28: =+#REF! -> #REF! | D28: =+#REF! -> #REF! | E28: =+#REF! -> #REF! | G28: =IF(D28="","",VLOOKUP(MID(A28,1,7),#REF!,3,FALSE)) -> #REF! | H28: =+#REF! -> #REF! | I28: =+#REF! -> #REF! | J28: =+#REF! -> #REF! | K28: =+#REF! -> #REF! | M28: =+VACANTES!H28 -> 55 | N28: =+VACANTES!I28 -> 0 | O28: =+VACANTES!J28 -> 0 | P28: =+VACANTES!K28 -> 5 | Q28: =+VACANTES!L28 -> 0 | R28: =+VACANTES!N28 -> 60 | S28: =+R28-Q28 -> 60
A29: =+#REF! -> #REF! | B29: =+#REF! -> #REF! | C29: =+#REF! -> #REF! | D29: =+#REF! -> #REF! | E29: =+#REF! -> #REF! | G29: =IF(D29="","",VLOOKUP(MID(A29,1,7),#REF!,3,FALSE)) -> #REF! | H29: =+#REF! -> #REF! | I29: =+#REF! -> #REF! | J29: =+#REF! -> #REF! | K29: =+#REF! -> #REF! | M29: =+VACANTES!H29 -> 60 | N29: =+VACANTES!I29 -> 0 | O29: =+VACANTES!J29 -> 0 | P29: =+VACANTES!K29 -> 0 | Q29: =+VACANTES!L29 -> 5 | R29: =+VACANTES!N29 -> 65 | S29: =+R29-Q29 -> 60
A30: =+#REF! -> #REF! | B30: =+#REF! -> #REF! | C30: =+#REF! -> #REF! | D30: =+#REF! -> #REF! | E30: =+#REF! -> #REF! | F30: 5573978-1 | G30: =IF(D30="","",VLOOKUP(MID(A30,1,7),#REF!,3,FALSE)) -> #REF! | H30: =+#REF! -> #REF! | I30: =+#REF! -> #REF! | J30: =+#REF! -> #REF! | K30: =+#REF! -> #REF! | M30: =+VACANTES!H30 -> 60 | N30: =+VACANTES!I30 -> 0 | O30: =+VACANTES!J30 -> 0 | P30: =+VACANTES!K30 -> 0 | Q30: =+VACANTES!L30 -> 5 | R30: =+VACANTES!N30 -> 65 | S30: =+R30-Q30 -> 60
A31: =+#REF! -> #REF! | B31: =+#REF! -> #REF! | C31: =+#REF! -> #REF! | D31: =+#REF! -> #REF! | E31: =+#REF! -> #REF! | F31: 2285027-K | G31: =IF(D31="","",VLOOKUP(MID(A31,1,7),#REF!,3,FALSE)) -> #REF! | H31: =+#REF! -> #REF! | I31: =+#REF! -> #REF! | J31: =+#REF! -> #REF! | K31: =+#REF! -> #REF! | M31: =+VACANTES!H31 -> 60 | N31: =+VACANTES!I31 -> 0 | O31: =+VACANTES!J31 -> 0 | P31: =+VACANTES!K31 -> 5 | Q31: =+VACANTES!L31 -> 5 | R31: =+VACANTES!N31 -> 70 | S31: =+R31-Q31 -> 65
A32: =+#REF! -> #REF! | B32: =+#REF! -> #REF! | C32: =+#REF! -> #REF! | D32: =+#REF! -> #REF! | E32: =+#REF! -> #REF! | F32: 7006273-9 | G32: =IF(D32="","",VLOOKUP(MID(A32,1,7),#REF!,3,FALSE)) -> #REF! | H32: =+#REF! -> #REF! | I32: =+#REF! -> #REF! | J32: =+#REF! -> #REF! | K32: =+#REF! -> #REF! | M32: =+VACANTES!H32 -> 60 | N32: =+VACANTES!I32 -> 0 | O32: =+VACANTES!J32 -> 0 | P32: =+VACANTES!K32 -> 5 | Q32: =+VACANTES!L32 -> 5 | R32: =+VACANTES!N32 -> 70 | S32: =+R32-Q32 -> 65
A33: =+#REF! -> #REF! | B33: =+#REF! -> #REF! | C33: =+#REF! -> #REF! | D33: =+#REF! -> #REF! | E33: =+#REF! -> #REF! | F33: 9156819-5 | G33: =IF(D33="","",VLOOKUP(MID(A33,1,7),#REF!,3,FALSE)) -> #REF! | J33: =+#REF! -> #REF! | K33: =+#REF! -> #REF! | M33: =+VACANTES!H33 -> 55 | N33: =+VACANTES!I33 -> 0 | O33: =+VACANTES!J33 -> 0 | P33: =+VACANTES!K33 -> 5 | Q33: =+VACANTES!L33 -> 2 | R33: =+VACANTES!N33 -> 62 | S33: =+R33-Q33 -> 60
A34: =+#REF! -> #REF! | B34: =+#REF! -> #REF! | C34: =+#REF! -> #REF! | D34: =+#REF! -> #REF! | E34: =+#REF! -> #REF! | F34: 10107406-4 | G34: =IF(D34="","",VLOOKUP(MID(A34,1,7),#REF!,3,FALSE)) -> #REF! | H34: =+#REF! -> #REF! | I34: =+#REF! -> #REF! | J34: =+#REF! -> #REF! | K34: =+#REF! -> #REF! | M34: =+VACANTES!H34 -> 55 | N34: =+VACANTES!I34 -> 0 | O34: =+VACANTES!J34 -> 0 | P34: =+VACANTES!K34 -> 5 | Q34: =+VACANTES!L34 -> 2 | R34: =+VACANTES!N34 -> 62 | S34: =+R34-Q34 -> 60
A35: =+#REF! -> #REF! | B35: =+#REF! -> #REF! | C35: =+#REF! -> #REF! | D35: =+#REF! -> #REF! | E35: =+#REF! -> #REF! | G35: =IF(D35="","",VLOOKUP(MID(A35,1,7),#REF!,3,FALSE)) -> #REF! | H35: =+#REF! -> #REF! | I35: =+#REF! -> #REF! | J35: =+#REF! -> #REF! | K35: =+#REF! -> #REF! | M35: =+VACANTES!H35 -> 55 | N35: =+VACANTES!I35 -> 0 | O35: =+VACANTES!J35 -> 0 | P35: =+VACANTES!K35 -> 5 | Q35: =+VACANTES!L35 -> 0 | R35: =+VACANTES!N35 -> 60 | S35: =+R35-Q35 -> 60
A36: =+#REF! -> #REF! | B36: =+#REF! -> #REF! | C36: =+#REF! -> #REF! | D36: =+#REF! -> #REF! | E36: =+#REF! -> #REF! | G36: =IF(D36="","",VLOOKUP(MID(A36,1,7),#REF!,3,FALSE)) -> #REF! | H36: =#REF! -> #REF! | I36: =+#REF! -> #REF! | J36: =+#REF! -> #REF! | K36: =+#REF! -> #REF! | M36: =+VACANTES!H36 -> 55 | N36: =+VACANTES!I36 -> 0 | O36: =+VACANTES!J36 -> 20 | P36: =+VACANTES!K36 -> 3 | Q36: =+VACANTES!L36 -> 0 | R36: =+VACANTES!N36 -> 78 | S36: =+R36-Q36 -> 78
A37: =+#REF! -> #REF! | B37: =+#REF! -> #REF! | C37: =+#REF! -> #REF! | D37: =+#REF! -> #REF! | E37: =+#REF! -> #REF! | G37: =IF(D37="","",VLOOKUP(MID(A37,1,7),#REF!,3,FALSE)) -> #REF! | H37: =+#REF! -> #REF! | I37: =+#REF! -> #REF! | J37: =+#REF! -> #REF! | K37: =+#REF! -> #REF! | M37: =+VACANTES!H37 -> 55 | N37: =+VACANTES!I37 -> 0 | O37: =+VACANTES!J37 -> 20 | P37: =+VACANTES!K37 -> 3 | Q37: =+VACANTES!L37 -> 0 | R37: =+VACANTES!N37 -> 78 | S37: =+R37-Q37 -> 78
A38: =+#REF! -> #REF! | B38: =+#REF! -> #REF! | C38: =+#REF! -> #REF! | D38: =+#REF! -> #REF! | E38: =+#REF! -> #REF! | F38: 5486416-7 | G38: =IF(D38="","",VLOOKUP(MID(A38,1,7),#REF!,3,FALSE)) -> #REF! | H38: =+#REF! -> #REF! | I38: =+#REF! -> #REF! | J38: =+#REF! -> #REF! | K38: =+#REF! -> #REF! | M38: =+VACANTES!H38 -> 63 | N38: =+VACANTES!I38 -> 0 | O38: =+VACANTES!J38 -> 7 | P38: =+VACANTES!K38 -> 0 | Q38: =+VACANTES!L38 -> 0 | R38: =+VACANTES!N38 -> 70 | S38: =+R38-Q38 -> 70
A39: =+#REF! -> #REF! | B39: =+#REF! -> #REF! | C39: =+#REF! -> #REF! | D39: =+#REF! -> #REF! | E39: =+#REF! -> #REF! | F39: 6443418-7 | G39: =IF(D39="","",VLOOKUP(MID(A39,1,7),#REF!,3,FALSE)) -> #REF! | H39: =+#REF! -> #REF! | I39: =+#REF! -> #REF! | J39: =+#REF! -> #REF! | K39: =+#REF! -> #REF! | M39: =+VACANTES!H39 -> 63 | N39: =+VACANTES!I39 -> 0 | O39: =+VACANTES!J39 -> 7 | P39: =+VACANTES!K39 -> 0 | Q39: =+VACANTES!L39 -> 0 | R39: =+VACANTES!N39 -> 70 | S39: =+R39-Q39 -> 70
A40: =+#REF! -> #REF! | B40: =+#REF! -> #REF! | C40: =+#REF! -> #REF! | D40: =+#REF! -> #REF! | E40: =+#REF! -> #REF! | F40: 8542877-2 | G40: =IF(D40="","",VLOOKUP(MID(A40,1,7),#REF!,3,FALSE)) -> #REF! | H40: =+#REF! -> #REF! | I40: =+#REF! -> #REF! | J40: =+#REF! -> #REF! | K40: =+#REF! -> #REF! | M40: =+VACANTES!H40 -> 63 | N40: =+VACANTES!I40 -> 0 | O40: =+VACANTES!J40 -> 7 | P40: =+VACANTES!K40 -> 0 | Q40: =+VACANTES!L40 -> 0 | R40: =+VACANTES!N40 -> 70 | S40: =+R40-Q40 -> 70
A43: CURSOS OPTATIVOS LICENCIATURA | G43: =IF(D43="","",VLOOKUP(MID(A43,1,7),#REF!,3,FALSE))
...
